Workbook
Name Año_Arriendo: Arriendo!$U$2:$U$4
Name Año_Basicos: 'Servicios Básicos'!$U$2:$U$9
Name Año_Juridica: Pers.Juridica!$U$2:$U$8
Name Año_Operacion: 'Gastos de Operación'!$U$2:$U$39
Name Año_Prop.intelectual: 'Prop. Intelectual'!$U$2:$U$9
Name Año_RRHH: RRHH!$W$2:$W$24
Name ARRIENDO: #REF!
Name CARGO: #REF!
Name CONTRATOS_CON_PERSONA_JURÍDICAS: #REF!
Name CUENTAS: #REF!
Name FORMA_DE_PAGO: #REF!
Name GASTOS_DE_INVERSION: #REF!
Name GASTOS_DE_OPERACIÓN: #REF!
Name Mes_Arriendo: Arriendo!$T$2:$T$4
Name Mes_Basicos: 'Servicios Básicos'!$T$2:$T$9
Name Mes_juridica: Pers.Juridica!$T$2:$T$8
Name Mes_Operacion: 'Gastos de Operación'!$T$2:$T$39
Name Mes_Prop.Intelectual: 'Prop. Intelectual'!$T$2:$T$9
Name Mes_RRHH: RRHH!$V$2:$V$24
Name PROPIEDAD_INTELECTUAL: #REF!
Name RRHH: #REF!
Name SERVICIOS_BÁSICOS: #REF!
Name TIPO_DE_DOCUMENTOS_GASTOS: #REF!
Name TIPO_DE_DOCUMENTOS_RRHH: #REF!
Name Valor_Rendido_Arriendo: Arriendo!$M$2:$M$4
Name Valor_Rendido_Basicos: 'Servicios Básicos'!$M$2:$M$9
Name Valor_Rendido_Juridica: Pers.Juridica!$M$2:$M$8
Name Valor_Rendido_Operacion: 'Gastos de Operación'!$M$2:$M$39
Name Valor_Rendido_Prop.Intelectual: 'Prop. Intelectual'!$M$2:$M$9
Name Valor_Rendido_Prop.Intelectual: 'Prop. Intelectual'!$M$2:$M$9
Name Valor_Rendido_RRHH: RRHH!$O$2:$O$2

Sheet ANTES DE EMPEZAR
B2: ANTES DE EMPEZAR
B4: Matriz_IPC | C4: Confirmar que esté completa la información del año a fiscalizar
B6: Fisc_Final | C6: Confirmar que el año esté haciendo referencia al año de los gastos a fiscalizar.
C7: Asegurar que la información del cliente y del proyecto.
C8: Asegurar que la suma de las cuentas corresponda al monto fiscalizado.
B10: Resumen | C10: Asegurar que la información del cliente y del proyecto.
C11: Asegurar que la suma de las cuentas corresponda al monto fiscalizado.
B13: Disponible | C13: Completar la información del disponible en base a lo certificado/modificado, según corresponda.

Sheet RRHH
A1: Cuenta | B1: Ítem | C1: Codigo | D1: RUT Contribuyente | E1: RUT RRHH | F1: Nombre del RRHH | G1: Tipo documento | H1: N° Documento | I1: Fecha Emision Documento | J1: Fecha de Pago Real | K1: Forma de Pago | L1: Total Haberes Total Boleta | M1: Total de horas contratadas. | N1: Horas dedicadas al proyecto | O1: Valor Rendido al Proyecto | P1: Glosa/Justificación | R1: Documento Tributario | S1: Comprobante de pago | T1: Observaciones | V1: Mes | W1: Año
A2: RRHH | B2: Director | C2: 1 | D2: 987654321 | E2: 12345678A | F2: Pedro Papas | G2: LIQ. SUELDO | H2: 112025 | I2: 45986 | J2: 45989 | K2: Transferencia electrónica | L2: 3952093 | M2: 180 | N2: 42 | O2: 922155 | P2: LIQUIDACIÓN NOVIEMBRE | V2: 11 | W2: 2025
A3: RRHH | B3: Director | C3: 1 | D3: 987654321 | E3: 12345678A | F3: Pedro Papas | G3: LIQ. SUELDO | H3: 122025 | I3: 46021 | J3: 46021 | K3: Transferencia electrónica | L3: 3952093 | M3: 180 | N3: 800 | O3: 200000000003 | P3: LIQUIDACIÓN DICIEMBRE | V3: 12 | W3: 2025
A4: RRHH | V4: 1 | W4: 1900
A5: RRHH | B5: Investigador | C5: 2 | D5: 987654321 | E5: 12345678B | F5: Juan Fuentes | G5: LIQ. SUELDO | H5: 112025 | I5: 45989 | J5: 45989 | K5: Transferencia electrónica | L5: 2340708 | M5: 180 | N5: 126 | O5: 1638496 | P5: LIQUIDACIÓN NOVIEMBRE | V5: 11 | W5: 2025
A6: RRHH | B6: Investigador | C6: 2 | D6: 987654321 | E6: 12345678B | F6: Juan Fuentes | G6: LIQ. SUELDO | H6: 122025 | I6: 46021 | J6: 46021 | K6: Transferencia electrónica | L6: 2340708 | M6: 180 | N6: 126 | O6: 1638496 | P6: LIQUIDACIÓN DICIEMBRE | V6: 12 | W6: 2025
A7: RRHH | V7: 1 | W7: 1900
A8: RRHH | B8: Investigador | C8: 3 | D8: 987654321 | E8: 12345678C | F8: Maria la del barrio | G8: LIQ. SUELDO | H8: 112025 | I8: 45989 | J8: 45989 | K8: Transferencia electrónica | L8: 2359239 | M8: 150 | N8: 126 | O8: 20 | P8: LIQUIDACIÓN NOVIEMBRE | V8: 11 | W8: 2025
A9: RRHH | B9: Investigador | C9: 3 | D9: 987654321 | E9: 12345678C | F9: Maria la del barrio | G9: LIQ. SUELDO | H9: 122025 | I9: 46021 | J9: 46021 | K9: Transferencia electrónica | L9: 2359239 | M9: 180 | N9: 126 | O9: 1651467 | P9: LIQUIDACIÓN DICIEMBRE | V9: 12 | W9: 2025
A10: RRHH | V10: 1 | W10: 1900
A11: RRHH | B11: Investigador | C11: 4 | D11: 987654321 | E11: 12345678D | F11: Antonio Caracas | G11: Liquidacion | H11: 112025 | I11: 45989 | J11: 45989 | K11: Transferencia electrónica | L11: 1855929 | M11: 180 | N11: 126 | O11: 1299150 | P11: LIQUIDACIÓN NOVIEMBRE | V11: 11 | W11: 2025
A12: RRHH | B12: Investigador | C12: 4 | D12: 987654321 | E12: 12345678D | F12: Antonio Caracas | G12: LIQ. SUELDO | H12: 122025 | I12: 46021 | J12: 46021 | K12: Transferencia electrónica | L12: 1855929 | M12: 180 | N12: 126 | O12: 1299150 | P12: LIQUIDACIÓN DICIEMBRE | V12: 12 | W12: 2025
A13: RRHH | V13: 1 | W13: 1900
A14: RRHH | B14: Técnico | C14: 5 | D14: 987654321 | E14: 12345678E | F14: Jose Perez | G14: Liquidacion | H14: 112025 | I14: 45989 | J14: 45989 | K14: Transferencia electrónica | L14: 2303499 | M14: 180 | N14: 42 | O14: 537483 | P14: LIQUIDACIÓN NOVIEMBRE | V14: 11 | W14: 2025
A15: RRHH | B15: Técnico | C15: 5 | D15: 987654321 | E15: 12345678E | F15: Jose Perez | G15: LIQ. SUELDO | H15: 122025 | I15: 46021 | J15: 46021 | K15: Transferencia electrónica | L15: 2163892 | M15: 168 | N15: 42 | O15: 540973 | P15: LIQUIDACIÓN DICIEMBRE | V15: 12 | W15: 2025
A16: RRHH | V16: 1 | W16: 1900
A17: RRHH | B17: Técnico | C17: 6 | D17: 987654321 | E17: 12345678F | F17: Paquita la del barrio | G17: Liquidacion | H17: 112025 | I17: 45989 | J17: 45989 | K17: Transferencia electrónica | L17: 2158685 | M17: 180 | N17: 42 | O17: 503693 | P17: LIQUIDACIÓN NOVIEMBRE | V17: 11 | W17: 2025
A18: RRHH | B18: Técnico | C18: 6 | D18: 987654321 | E18: 12345678F | F18: Paquita la del barrio | G18: LIQ. SUELDO | H18: 122025 | I18: 46021 | J18: 46021 | K18: Transferencia electrónica | L18: 2158685 | M18: 180 | N18: 42 | O18: 503693 | P18: LIQUIDACIÓN DICIEMBRE | V18: 12 | W18: 2025
A19: RRHH | V19: 1 | W19: 1900
A20: RRHH | V20: 1 | W20: 1900
A23: Total | L23: =SUBTOTAL(109,RRHH!$L$2:$L$2) -> 3952093 | N23: =SUBTOTAL(109,RRHH!$N$2:$N$2) -> 42 | O23: =SUM(O2:O2) -> 922155 | V23: =MONTH(RRHH!$J23) -> 1 | W23: =YEAR(RRHH!$J23) -> 1900
V24: =MONTH(RRHH!$J24) -> 1 | W24: =YEAR(RRHH!$J24) -> 1900

Sheet Gastos de Operación
A1: Cuenta | B1: Ítem | C1: Código | D1: RUT Contribuyente | E1: RUT Proveedor | F1: Nombre Proveedor o Razón Social | G1: Tipo documento | H1: N° Documento | I1: Fecha Emisión Documento | J1: Fecha Pago Real | K1: Forma de Pago | L1: Monto Total Documento (V. Neto) | M1: Valor Rendido al Proyecto | N1: Glosa / Justificación | P1: Documento Tributario | Q1: Comprobante de pago | R1: Observaciones | T1: Mes | U1: Año
A2: GASTOS DIRECTOS | B2: Fertilizantes | C2: =IFERROR(VLOOKUP(B2,#REF!,5,FALSE),"") | D2: 987654321 | E2: 737738897 | F2: PWC | G2: Facturas | H2: 994322 | I2: 45754 | J2: 45806 | K2: Transferencia electrónica | L2: 29630255 | M2: 29630255 | N2: Bellis | T2: =MONTH('Gastos de Operación'!$J2) -> 5 | U2: =YEAR('Gastos de Operación'!$J2) -> 2025
A3: GASTOS DIRECTOS | B3: Fertilizantes | C3: =IFERROR(VLOOKUP(B3,#REF!,5,FALSE),"") | D3: 987654321 | E3: 933838778 | F3: CocaCola | G3: Facturas | H3: 2101286 | I3: 45755 | J3: 45820 | K3: Transferencia electrónica | L3: 18923265 | M3: 18923265 | N3: Coragen | T3: =MONTH('Gastos de Operación'!$J3) -> 6 | U3: =YEAR('Gastos de Operación'!$J3) -> 2025
A4: GASTOS DIRECTOS | B4: Fertilizantes | C4: =IFERROR(VLOOKUP(B4,#REF!,5,FALSE),"") | D4: 987654321 | E4: 773773779 | F4: Vaqueritos | G4: Factura | H4: 220 | I4: 45757 | J4: 45786 | K4: Transferencia electrónica | L4: 12856961 | M4: 12856961 | N4: Cantus | T4: =MONTH('Gastos de Operación'!$J4) -> 5 | U4: =YEAR('Gastos de Operación'!$J4) -> 2025
A5: GASTOS DIRECTOS | B5: Fertilizantes | C5: =IFERROR(VLOOKUP(B5,#REF!,5,FALSE),"") | D5: 987654321 | E5: 933838778 | F5: CocaCola | G5: Factura | H5: 2101265 | I5: 45755 | J5: 45813 | K5: Transferencia electrónica | L5: 12111569 | M5: 12111569 | N5: Muralla Delta 190 | T5: =MONTH('Gastos de Operación'!$J5) -> 6 | U5: =YEAR('Gastos de Operación'!$J5) -> 2025
A6: GASTOS DIRECTOS | B6: Fertilizantes | C6: =IFERROR(VLOOKUP(B6,#REF!,5,FALSE),"") | D6: 987654321 | E6: 837978773 | F6: Pepsi | G6: Factura | H6: 5990677 | I6: 45756 | J6: 45827 | K6: Transferencia electrónica | L6: 9515952 | M6: 9515952 | N6: Centurion Super | T6: =MONTH('Gastos de Operación'!$J6) -> 6 | U6: =YEAR('Gastos de Operación'!$J6) -> 2025
A7: GASTOS DIRECTOS | B7: Fertilizantes | C7: =IFERROR(VLOOKUP(B7,#REF!,5,FALSE),"") | D7: 987654321 | E7: 737738897 | F7: PWC | G7: Factura | H7: 994873 | I7: 45754 | J7: 45806 | K7: Transferencia electrónica | L7: 9011942 | M7: 9011942 | N7: Intrepid (1Lt) DW | T7: =MONTH('Gastos de Operación'!$J7) -> 5 | U7: =YEAR('Gastos de Operación'!$J7) -> 2025
A8: GASTOS DIRECTOS | B8: Fertilizantes | C8: =IFERROR(VLOOKUP(B8,#REF!,5,FALSE),"") | D8: 987654321 | E8: 933937373 | F8: Lays | G8: Factura | H8: 244663 | I8: 45758 | J8: 45786 | K8: Transferencia electrónica | L8: 7256559 | M8: 7256559 | N8: Herbadox 455 SC | T8: =MONTH('Gastos de Operación'!$J8) -> 5 | U8: =YEAR('Gastos de Operación'!$J8) -> 2025
A9: GASTOS DIRECTOS | B9: Fertilizantes | C9: =IFERROR(VLOOKUP(B9,#REF!,5,FALSE),"") | D9: 987654321 | E9: 933838778 | F9: CocaCola | G9: Factura | H9: 2101262 | I9: 45755 | J9: 45813 | K9: Transferencia electrónica | L9: 6766415 | M9: 6766415 | N9: Amistar Opti | T9: =MONTH('Gastos de Operación'!$J9) -> 6 | U9: =YEAR('Gastos de Operación'!$J9) -> 2025
A10: GASTOS DIRECTOS | B10: Fertilizantes | C10: =IFERROR(VLOOKUP(B10,#REF!,5,FALSE),"") | D10: 987654321 | E10: 933777378 | F10: Sgs | G10: Factura | H10: 2062878 | I10: 45708 | J10: 45736 | K10: Transferencia electrónica | L10: 5953500 | M10: 5953500 | N10: Tsunami 100 | T10: =MONTH('Gastos de Operación'!$J10) -> 3 | U10: =YEAR('Gastos de Operación'!$J10) -> 2025
A11: GASTOS DIRECTOS | B11: Fertilizantes | C11: =IFERROR(VLOOKUP(B11,#REF!,5,FALSE),"") | D11: 987654321 | E11: 837978773 | F11: Pepsi | G11: Factura | H11: 5990661 | I11: 45756 | J11: 45813 | K11: Transferencia electrónica | L11: 5489254 | M11: 5489254 | N11: Priori Xtra | T11: =MONTH('Gastos de Operación'!$J11) -> 6 | U11: =YEAR('Gastos de Operación'!$J11) -> 2025
A12: GASTOS DIRECTOS | B12: Fertilizantes | C12: =IFERROR(VLOOKUP(B12,#REF!,5,FALSE),"") | D12: 987654321 | E12: 738993887 | F12: Deloit | G12: Factura | H12: 360 | I12: 45789 | J12: 45820 | K12: Transferencia electrónica | L12: 6530480 | M12: 6530480 | N12: GUANO DE VACUNO | T12: =MONTH('Gastos de Operación'!$J12) -> 6 | U12: =YEAR('Gastos de Operación'!$J12) -> 2025
A13: GASTOS DIRECTOS | B13: Fertilizantes | C13: =IFERROR(VLOOKUP(B13,#REF!,5,FALSE),"") | D13: 987654321 | E13: 737779778 | F13: SalmonesPro | G13: Factura | H13: 5852 | I13: 45730 | J13: 45757 | K13: Transferencia electrónica | L13: 6380000 | M13: 6380000 | N13: Guano rojo fosil (polvo) | T13: =MONTH('Gastos de Operación'!$J13) -> 4 | U13: =YEAR('Gastos de Operación'!$J13) -> 2025
... A20: GASTOS DIRECTOS | B20: Materiales e Insumos | C20: =IFERROR(VLOOKUP(B20,#REF!,5,FALSE),"") | D20: 987654321 | E20: 737879773 | F20: ExcelPro | G20: Factura | H20: 165241 | I20: 45699 | J20: 45729 | K20: Transferencia electrónica | L20: 6190000 | M20: 6190000 | N20: Materiales Mantencion Construccion | T20: =MONTH('Gastos de Operación'!$J20) -> 3 | U20: =YEAR('Gastos de Operación'!$J20) -> 2025
A21: GASTOS DIRECTOS | B21: Almácigos e injertos | C21: =IFERROR(VLOOKUP(B21,#REF!,5,FALSE),"") | D21: 987654321 | E21: 73377837K | F21: Khua | G21: Factura | H21: 26981 | I21: 45728 | J21: 45743 | K21: Transferencia electrónica | L21: 2538800 | M21: 2538800 | N21: Servicio de produccion almacigos | T21: =MONTH('Gastos de Operación'!$J21) -> 3 | U21: =YEAR('Gastos de Operación'!$J21) -> 2025
A22: GASTOS DIRECTOS | B22: Almácigos e injertos | C22: =IFERROR(VLOOKUP(B22,#REF!,5,FALSE),"") | D22: 987654321 | E22: 77373777K | F22: AcerosPros | G22: Factura | H22: 410890 | I22: 45748 | J22: 45779 | K22: Transferencia electrónica | L22: 1645590 | M22: 1645590 | N22: Servicio de produccion almacigos | T22: =MONTH('Gastos de Operación'!$J22) -> 5 | U22: =YEAR('Gastos de Operación'!$J22) -> 2025
A23: GASTOS DIRECTOS | B23: Almácigos e injertos | C23: =IFERROR(VLOOKUP(B23,#REF!,5,FALSE),"") | D23: 987654321 | E23: 77373777K | F23: AcerosPros | G23: Factura | H23: 416393 | I23: 45813 | J23: 45868 | K23: Transferencia electrónica | L23: 1152000 | M23: 1152000 | N23: Servicio de produccion almacigos | T23: =MONTH('Gastos de Operación'!$J23) -> 7 | U23: =YEAR('Gastos de Operación'!$J23) -> 2025
A24: GASTOS DIRECTOS | B24: Materiales de laboratorio | C24: =IFERROR(VLOOKUP(B24,#REF!,5,FALSE),"") | D24: 987654321 | E24: 777389377 | F24: D1 | G24: Factura | H24: 101427 | I24: 45644 | J24: 45673 | K24: Transferencia electrónica | L24: 1374671 | M24: 1374671 | N24: Materiales Laboratorio | T24: =MONTH('Gastos de Operación'!$J24) -> 1 | U24: =YEAR('Gastos de Operación'!$J24) -> 2025
A25: GASTOS DIRECTOS | B25: Materiales de laboratorio | C25: =IFERROR(VLOOKUP(B25,#REF!,5,FALSE),"") | D25: 987654321 | E25: 778777377 | F25: Ara | G25: Factura | H25: 170004 | I25: 45713 | J25: 45743 | K25: Transferencia electrónica | L25: 598800 | M25: 598800 | N25: Materiales Laboratorio | T25: =MONTH('Gastos de Operación'!$J25) -> 3 | U25: =YEAR('Gastos de Operación'!$J25) -> 2025
A26: GASTOS DIRECTOS | B26: EPP (Equipo de protección personal) | C26: =IFERROR(VLOOKUP(B26,#REF!,5,FALSE),"") | D26: 987654321 | E26: 838877777 | F26: Caruya | G26: Factura | H26: 3242541 | I26: 45680 | J26: 45708 | K26: Transferencia electrónica | L26: 947060 | M26: 947060 | N26: Guante Quirurgico en Caja | T26: =MONTH('Gastos de Operación'!$J26) -> 2 | U26: =YEAR('Gastos de Operación'!$J26) -> 2025
A27: GASTOS DIRECTOS | B27: EPP (Equipo de protección personal) | C27: =IFERROR(VLOOKUP(B27,#REF!,5,FALSE),"") | D27: 987654321 | E27: 838877777 | F27: Caruya | G27: Factura | H27: 3207791 | I27: 45635 | J27: 45666 | K27: Transferencia electrónica | L27: 428761 | M27: 428761 | N27: GUANTE NINJA REBEL (Unids) | T27: =MONTH('Gastos de Operación'!$J27) -> 1 | U27: =YEAR('Gastos de Operación'!$J27) -> 2025
A28: GASTOS DIRECTOS | B28: EPP (Equipo de protección personal) | C28: =IFERROR(VLOOKUP(B28,#REF!,5,FALSE),"") | D28: 987654321 | E28: 838877777 | F28: Caruya | G28: Factura | H28: 3253100 | I28: 45691 | J28: 45722 | K28: Transferencia electrónica | L28: 423810 | M28: 423810 | N28: Guante Quirurgico en Caja | T28: =MONTH('Gastos de Operación'!$J28) -> 3 | U28: =YEAR('Gastos de Operación'!$J28) -> 2025
A29: GASTOS DIRECTOS | B29: Fletes | C29: =IFERROR(VLOOKUP(B29,#REF!,5,FALSE),"") | D29: 987654321 | E29: 333738338 | F29: AndresCarnes | G29: Factura | H29: 121 | I29: 45656 | J29: 45673 | K29: Transferencia electrónica | L29: 2390000 | M29: 2390000 | N29: Fletes Nacionales | T29: =MONTH('Gastos de Operación'!$J29) -> 1 | U29: =YEAR('Gastos de Operación'!$J29) -> 2025
A30: GASTOS DIRECTOS | B30: Fletes | C30: =IFERROR(VLOOKUP(B30,#REF!,5,FALSE),"") | D30: 987654321 | E30: 333738338 | F30: AndresCarnes | G30: Factura | H30: 119 | I30: 46021 | J30: 45673 | K30: Transferencia electrónica | L30: 2160000 | M30: 2160000 | N30: Fletes Nacionales | T30: =MONTH('Gastos de Operación'!$J30) -> 1 | U30: =YEAR('Gastos de Operación'!$J30) -> 2025
A31: GASTOS DIRECTOS | B31: Fletes | C31: =IFERROR(VLOOKUP(B31,#REF!,5,FALSE),"") | D31: 987654321 | E31: 333738338 | F31: AndresCarnes | G31: Factura | H31: 120 | I31: 46021 | J31: 45673 | K31: Transferencia electrónica | L31: 1970000 | M31: 1970000 | N31: Fletes Nacionales | T31: =MONTH('Gastos de Operación'!$J31) -> 1 | U31: =YEAR('Gastos de Operación'!$J31) -> 2025
A32: GASTOS DIRECTOS | B32: EPP (Equipo de protección personal) | C32: =IFERROR(VLOOKUP(B32,#REF!,5,FALSE),"") | D32: 987654321 | E32: 787837873 | F32: FalcaoCorp | G32: Factura | H32: 82747 | I32: 45805 | J32: 45834 | K32: Transferencia electrónica | L32: 1925960 | M32: 1925960 | N32: Materiales Laboratorio | T32: =MONTH('Gastos de Operación'!$J32) -> 6 | U32: =YEAR('Gastos de Operación'!$J32) -> 2025
A33: GASTOS DIRECTOS | B33: Fletes | C33: =IFERROR(VLOOKUP(B33,#REF!,5,FALSE),"") | D33: 987654321 | E33: 373939938 | F33: AntonioCorp | G33: Factura | H33: 227 | I33: 45722 | J33: 45736 | K33: Transferencia electrónica | L33: 1900000 | M33: 1900000 | N33: Fletes Nacionales | T33: =MONTH('Gastos de Operación'!$J33) -> 3 | U33: =YEAR('Gastos de Operación'!$J33) -> 2025
A34: GASTOS DIRECTOS | B34: Fletes | C34: =IFERROR(VLOOKUP(B34,#REF!,5,FALSE),"") | D34: 987654321 | E34: 379338773 | F34: AntoniaCorp | G34: Factura | H34: 362 | I34: 45740 | J34: 45820 | K34: Transferencia electrónica | L34: 1476400 | M34: 1476400 | N34: Fletes Nacionales | T34: =MONTH('Gastos de Operación'!$J34) -> 6 | U34: =YEAR('Gastos de Operación'!$J34) -> 2025
A35: GASTOS DIRECTOS | B35: Materiales e Insumos | C35: =IFERROR(VLOOKUP(B35,#REF!,5,FALSE),"") | D35: 987654321 | E35: 379788739 | F35: MariaCorp | G35: Factura | H35: 8125 | I35: 45701 | J35: 45729 | K35: Transferencia electrónica | L35: 564900 | M35: 564900 | N35: CINTA DE TERMOTRANSFERENCIA 110x74 MTS | T35: =MONTH('Gastos de Operación'!$J35) -> 3 | U35: =YEAR('Gastos de Operación'!$J35) -> 2025
... A40: GASTOS DIRECTOS | B40: Materiales e Insumos | C40: =IFERROR(VLOOKUP(B40,#REF!,5,FALSE),"") | D40: 987654321 | E40: 777778777 | F40: Delipollo | G40: Factura | H40: 1564 | I40: 45881 | J40: 45911 | K40: Transferencia electrónica | L40: 39456050 | M40: 39456050 | N40: Antiafido | T40: =MONTH('Gastos de Operación'!$J40) -> 9 | U40: =YEAR('Gastos de Operación'!$J40) -> 2025
A41: GASTOS DIRECTOS | B41: Fertilizantes | C41: =IFERROR(VLOOKUP(B41,#REF!,5,FALSE),"") | D41: 987654321 | E41: 837978773 | F41: Pepsi | G41: Factura | H41: 6153832 | I41: 45892 | J41: 45953 | K41: Transferencia electrónica | L41: 18620525 | M41: =L41 -> 18620525 | N41: Nitrato potasio, magnesio,sulfato potasio | T41: =MONTH('Gastos de Operación'!$J41) -> 10 | U41: =YEAR('Gastos de Operación'!$J41) -> 2025
A42: GASTOS DIRECTOS | B42: Materiales e Insumos | C42: =IFERROR(VLOOKUP(B42,#REF!,5,FALSE),"") | D42: 987654321 | E42: 77373777k | F42: AcerosPros | G42: Factura | H42: 420977 | I42: 45868 | J42: 45897 | K42: Transferencia electrónica | L42: 10466479 | M42: =L42 -> 10466479 | N42: Monofilamento raschel | T42: =MONTH('Gastos de Operación'!$J42) -> 8 | U42: =YEAR('Gastos de Operación'!$J42) -> 2025
A43: GASTOS DIRECTOS | B43: Almácigos e injertos | C43: =IFERROR(VLOOKUP(B43,#REF!,5,FALSE),"") | D43: 987654321 | E43: 77373777k | F43: AcerosPros | G43: Factura | H43: 420703 | I43: 45866 | J43: 45904 | K43: Transferencia electrónica | L43: 7392960 | M43: 7392960 | N43: Turba XL | T43: =MONTH('Gastos de Operación'!$J43) -> 9 | U43: =YEAR('Gastos de Operación'!$J43) -> 2025
A44: GASTOS DIRECTOS | B44: Almácigos e injertos | C44: =IFERROR(VLOOKUP(B44,#REF!,5,FALSE),"") | D44: 987654321 | E44: 773787373 | F44: AgroYa | G44: Factura | H44: 313 | I44: 45950 | J44: 45960 | K44: Transferencia electrónica | L44: 7840770 | M44: =7840770-2524901.6 -> 5315868.4 | N44: plantas de envidia ($15c/u). 428744 plantas de lechuga ($15c/u). 14 | T44: =MONTH('Gastos de Operación'!$J44) -> 10 | U44: =YEAR('Gastos de Operación'!$J44) -> 2025
A45: GASTOS DIRECTOS | B45: Materiales de laboratorio | C45: =IFERROR(VLOOKUP(B45,#REF!,5,FALSE),"") | D45: 987654321 | E45: 787837873 | F45: FalcaoCorp | G45: Factura | H45: 85139 | I45: 45933 | J45: 45960 | K45: Transferencia electrónica | L45: 1053876 | M45: 1053876 | N45: Reactivos | T45: =MONTH('Gastos de Operación'!$J45) -> 10 | U45: =YEAR('Gastos de Operación'!$J45) -> 2025
A46: GASTOS DIRECTOS | B46: Materiales de laboratorio | C46: =IFERROR(VLOOKUP(B46,#REF!,5,FALSE),"") | D46: 987654321 | E46: 738893373 | F46: Kemist | G46: Factura | H46: 55610 | I46: 45898 | J46: 45911 | K46: Transferencia electrónica | L46: 687259 | M46: 687259 | N46: Reactivos | T46: =MONTH('Gastos de Operación'!$J46) -> 9 | U46: =YEAR('Gastos de Operación'!$J46) -> 2025
A47: GASTOS DIRECTOS | B47: Equipos de medición | C47: =IFERROR(VLOOKUP(B47,#REF!,5,FALSE),"") | D47: 987654321 | E47: 873738777 | F47: BetoCorp | G47: Factura | H47: 887965 | I47: 45939 | J47: 45974 | K47: Transferencia electrónica | L47: 2488800 | M47: =L47 -> 2488800 | N47: Tensiometro | T47: =MONTH('Gastos de Operación'!$J47) -> 11 | U47: =YEAR('Gastos de Operación'!$J47) -> 2025
A48: GASTOS DIRECTOS | B48: Equipos de medición | C48: =IFERROR(VLOOKUP(B48,#REF!,5,FALSE),"") | D48: 987654321 | E48: 873738777 | F48: BetoCorp | G48: Factura | H48: 887797 | I48: 45937 | J48: 45967 | K48: Transferencia electrónica | L48: 2099280 | M48: =L48 -> 2099280 | N48: Transmisor temperatura,gateway lorawan | T48: =MONTH('Gastos de Operación'!$J48) -> 11 | U48: =YEAR('Gastos de Operación'!$J48) -> 2025
A49: GASTOS DIRECTOS | B49: Equipos de medición | C49: =IFERROR(VLOOKUP(B49,#REF!,5,FALSE),"") | D49: 987654321 | E49: 873738777 | F49: BetoCorp | G49: Factura | H49: 887793 | I49: 45937 | J49: 45967 | K49: Transferencia electrónica | L49: 1848250 | M49: =L49 -> 1848250 | N49: tensiometros | T49: =MONTH('Gastos de Operación'!$J49) -> 11 | U49: =YEAR('Gastos de Operación'!$J49) -> 2025
A50: GASTOS DIRECTOS | B50: Equipos de medición | C50: =IFERROR(VLOOKUP(B50,#REF!,5,FALSE),"") | D50: 987654321 | E50: 739779833 | F50: Panelias | G50: Factura | H50: 664 | I50: 45891 | J50: 45904 | K50: Transferencia electrónica | L50: 117600 | M50: 117600 | N50: Medidor ORP ozono | T50: =MONTH('Gastos de Operación'!$J50) -> 9 | U50: =YEAR('Gastos de Operación'!$J50) -> 2025
...

Sheet Pers.Juridica
A1: Cuenta | B1: Ítem | C1: Código | D1: RUT Contribuyente | E1: RUT Proveedor | F1: Nombre Proveedor o Razón Social | G1: Tipo documento | H1: N° Documento | I1: Fecha Emisión Documento | J1: Fecha Pago Real | K1: Forma de Pago | L1: Monto Total Documento (V. Neto) | M1: Valor Rendido al Proyecto | N1: Glosa / Justificación | P1: Documento Tributario | Q1: Comprobante de pago | R1: Observaciones | T1: Mes | U1: Año
A2: PERSONA JURÍDICA | C2: =IFERROR(VLOOKUP(B2,#REF!,5,FALSE),"") | T2: =MONTH(Pers.Juridica!$J2) -> 1 | U2: =YEAR(Pers.Juridica!$J2) -> 1900
A3: PERSONA JURÍDICA | B3: Subcontrato1 | C3: =IFERROR(VLOOKUP(B3,#REF!,5,FALSE),"") | D3: 987654321 | E3: 113180545 | F3: AgroYa | G3: Factura | H3: 252 | I3: 45740 | J3: 45750 | K3: Transferencia electrónica | L3: 7320680 | M3: 6969287 | N3: Traslado de Personal/Lechuga, cosecha | T3: =MONTH(Pers.Juridica!$J3) -> 4 | U3: =YEAR(Pers.Juridica!$J3) -> 2025
A4: PERSONA JURÍDICA | B4: Subcontrato1 | C4: =IFERROR(VLOOKUP(B4,#REF!,5,FALSE),"") | D4: 987654321 | E4: 13101850K | F4: KhuaS.A. | G4: Factura | H4: 28134 | I4: 45826 | J4: 45841 | K4: Transferencia electrónica | L4: 7600374 | M4: 7600374 | N4: Servicio de produccion almacigos | T4: =MONTH(Pers.Juridica!$J4) -> 7 | U4: =YEAR(Pers.Juridica!$J4) -> 2025
A5: PERSONA JURÍDICA | B5: Subcontrato1 | C5: =IFERROR(VLOOKUP(B5,#REF!,5,FALSE),"") | D5: 987654321 | E5: 13101850K | F5: KhuaS.A. | G5: Factura | H5: 26892 | I5: 45721 | J5: 45736 | K5: Transferencia electrónica | L5: 7506721 | M5: 7506721 | N5: Servicio de produccion almacigos | T5: =MONTH(Pers.Juridica!$J5) -> 3 | U5: =YEAR(Pers.Juridica!$J5) -> 2025
A6: PERSONA JURÍDICA | B6: Subcontrato2 | C6: =IFERROR(VLOOKUP(B6,#REF!,5,FALSE),"") | D6: 987654321 | E6: 114303001 | F6: Chichilele | G6: Factura | H6: 45881 | I6: 45930 | J6: 45960 | K6: Transferencia electrónica | L6: 880000 | M6: 720000 | N6: Análisis nematológico | T6: =MONTH(Pers.Juridica!$J6) -> 10 | U6: =YEAR(Pers.Juridica!$J6) -> 2025
A7: PERSONA JURÍDICA | B7: Subcontrato2 | C7: =IFERROR(VLOOKUP(B7,#REF!,5,FALSE),"") | D7: 987654321 | E7: 813989000 | F7: Javerianos | G7: Factura | H7: 116209 | I7: 45891 | J7: 45911 | K7: Transferencia electrónica | L7: 783404 | M7: 522269 | N7: Analisis de suelo | T7: =MONTH(Pers.Juridica!$J7) -> 9 | U7: =YEAR(Pers.Juridica!$J7) -> 2025
A8: PERSONA JURÍDICA | T8: =MONTH(Pers.Juridica!$J8) -> 1 | U8: =YEAR(Pers.Juridica!$J8) -> 1900
A9: Total | L9: =SUBTOTAL(109,Pers.Juridica!$L$2:$L$8) -> 24091179 | M9: =SUBTOTAL(109,Pers.Juridica!$M$2:$M$8) -> 23318651 | T9: =MONTH(Pers.Juridica!$J9) -> 1 | U9: =YEAR(Pers.Juridica!$J9) -> 1900

Sheet Prop. Intelectual
A1: Cuenta | B1: Ítem | C1: Código | D1: RUT Contribuyente | E1: RUT Proveedor | F1: Nombre Proveedor o Razón Social | G1: Tipo documento | H1: N° Documento | I1: Fecha Emisión Documento | J1: Fecha Pago Real | K1: Forma de Pago | L1: Monto Total Documento (V. Neto) | M1: Valor Rendido al Proyecto | N1: Glosa / Justificación | P1: Documento Tributario | Q1: Comprobante de pago | R1: Observaciones | T1: Mes | U1: Año
A2: PROPIEDAD INTELECTUAL | C2: =IFERROR(VLOOKUP(B2,#REF!,5,FALSE),"") | T2: =MONTH('Prop. Intelectual'!$J2) -> 1 | U2: =YEAR('Prop. Intelectual'!$J2) -> 1900
A3: PROPIEDAD INTELECTUAL | C3: =IFERROR(VLOOKUP(B3,#REF!,5,FALSE),"") | T3: =MONTH('Prop. Intelectual'!$J3) -> 1 | U3: =YEAR('Prop. Intelectual'!$J3) -> 1900
A4: PROPIEDAD INTELECTUAL | C4: =IFERROR(VLOOKUP(B4,#REF!,5,FALSE),"") | T4: =MONTH('Prop. Intelectual'!$J4) -> 1 | U4: =YEAR('Prop. Intelectual'!$J4) -> 1900
A5: PROPIEDAD INTELECTUAL | C5: =IFERROR(VLOOKUP(B5,#REF!,5,FALSE),"") | T5: =MONTH('Prop. Intelectual'!$J5) -> 1 | U5: =YEAR('Prop. Intelectual'!$J5) -> 1900
A6: PROPIEDAD INTELECTUAL | C6: =IFERROR(VLOOKUP(B6,#REF!,5,FALSE),"") | T6: =MONTH('Prop. Intelectual'!$J6) -> 1 | U6: =YEAR('Prop. Intelectual'!$J6) -> 1900
A7: PROPIEDAD INTELECTUAL | C7: =IFERROR(VLOOKUP(B7,#REF!,5,FALSE),"") | T7: =MONTH('Prop. Intelectual'!$J7) -> 1 | U7: =YEAR('Prop. Intelectual'!$J7) -> 1900
A8: PROPIEDAD INTELECTUAL | C8: =IFERROR(VLOOKUP(B8,#REF!,5,FALSE),"") | T8: =MONTH('Prop. Intelectual'!$J8) -> 1 | U8: =YEAR('Prop. Intelectual'!$J8) -> 1900
A9: PROPIEDAD INTELECTUAL | C9: =IFERROR(VLOOKUP(B9,#REF!,5,FALSE),"") | T9: =MONTH('Prop. Intelectual'!$J9) -> 1 | U9: =YEAR('Prop. Intelectual'!$J9) -> 1900
A10: Total | L10: =SUBTOTAL(109,'Prop. Intelectual'!$L$2:$L$9) -> 0 | M10: =SUBTOTAL(109,'Prop. Intelectual'!$M$2:$M$9) -> 0
B13: TIPS DE INGRESO DE INFORMACIÓN (ELIMINAR ANTES DE ENVIAR A CLIENTE) Protección de la Propiedad Industrial, Intelectual o de Obtentores de nuevas variedades vegetales: Corresponde a todos los gastos incurridos en la constitución de derechos de propiedad industrial al amparo de la ley N° 19.039; de derechos de propiedad intelectual al amparo de la ley N°17.366, y de derechos de protección sobre nuevas variedades vegetales al amparo de la ley N°19.342, como resultado del proyecto de I+D.
D15: IMPORTANTE | F15: Las columnas T y U hacen referencia al mes y año del gasto. SIEMPRE deben estar configuradas
D17: RUT Proveedor | F17: En el caso de que proveedor sea internacional, completar con 999999999
D19: ÍTEM | F19: Se debe actualizar la lista desplegable desde el disponible. Considerar: DATOS>VALIDACIÓN DE DATOS>PERMITIR: LISTA
D21: TIPO DOCUMENTO | F21: Facturas emitidas por la entidad que prestó el servicio.
D23: FECHA PAGO REAL | F23: Fecha indicada por el comprobantes de pago de las tasas y derechos asociados con patentes, marcas, diseños industriales, servicios de asesoría, estudios de patentabilidad, informes periciales, entre otros (tales como transferencias bancarias, cheques u otros documentos que respalden las transacciones realizadas). En el caso de pago con nómina (que en un pagó se haya incluido más de una factura, se debe contar con el detalle de todas las facturas asociadas a este pago, independiente si corresponden o no al proyecto).
D25: GLOSA | F25: Revisar siempre que la glosa se encuentre en una sola línea y no contenga comas. Para separar elementos utilizar un guion.
F26: EJEMPLOS: Materiales de laboratorio, vidrio -> DEBE DECIR: Materiales de laboratorio - vidrio Materiales de -> DEBE DECIR: Materiales de laboratorio Laboratorio

Sheet Arriendo
A1: Cuenta | B1: Ítem | C1: Código | D1: RUT Contribuyente | E1: RUT Proveedor | F1: Nombre Proveedor o Razón Social | G1: Tipo documento | H1: N° Documento | I1: Fecha Emisión Documento | J1: Fecha Pago Real | K1: Forma de Pago | L1: Monto Total Documento (V. Neto) | M1: Valor Rendido al Proyecto | N1: Glosa / Justificación | P1: Documento Tributario | Q1: Comprobante de pago | R1: Observaciones | T1: Mes | U1: Año
A2: ARRIENDO | C2: =IFERROR(VLOOKUP(B2,#REF!,5,FALSE),"") | T2: =MONTH(Arriendo!$J2) -> 1 | U2: =YEAR(Arriendo!$J2) -> 1900
A3: ARRIENDO | B3: Arriendo de colmenas | C3: =IFERROR(VLOOKUP(B3,#REF!,5,FALSE),"") | D3: 987654321 | E3: 132780966 | F3: Comeba | G3: Factura | H3: 62 | I3: 45686 | J3: 45701 | K3: Transferencia electrónica | L3: 4050000 | M3: =4050000-867600 -> 3182400 | N3: Colmenas para polinizacione en arriendo | T3: =MONTH(Arriendo!$J3) -> 2 | U3: =YEAR(Arriendo!$J3) -> 2025
A4: ARRIENDO | C4: =IFERROR(VLOOKUP(B4,#REF!,5,FALSE),"") | T4: =MONTH(Arriendo!$J4) -> 1 | U4: =YEAR(Arriendo!$J4) -> 1900
A5: Total | L5: =SUBTOTAL(109,Arriendo!$L$2:$L$4) -> 4050000 | M5: =SUBTOTAL(109,Arriendo!$M$2:$M$4) -> 3182400

Sheet Servicios Básicos
A1: Cuenta | B1: Ítem | C1: Código | D1: RUT Contribuyente | E1: RUT Proveedor | F1: Nombre Proveedor o Razón Social | G1: Tipo documento | H1: N° Documento | I1: Fecha Emisión Documento | J1: Fecha Pago Real | K1: Forma de Pago | L1: Monto Total Documento (V. Neto) | M1: Valor Rendido al Proyecto | N1: Glosa / Justificación | P1: Documento Tributario | Q1: Comprobante de pago | R1: Observaciones | T1: Mes | U1: Año
A2: SERVICIOS BÁSICOS | C2: =IFERROR(VLOOKUP(B2,#REF!,5,FALSE),"") | T2: =MONTH('Servicios Básicos'!$J2) -> 1 | U2: =YEAR('Servicios Básicos'!$J2) -> 1900
A3: SERVICIOS BÁSICOS | B3: Gastos de servicios básicos | C3: 161001 | D3: 987654321 | E3: 965687408 | F3: Morat Gas | G3: Factura | H3: 11388531 | I3: 45762 | J3: 45792 | K3: Transferencia electrónica | L3: 4212280 | M3: 4212280 | N3: Gas Procesos Planta | T3: =MONTH('Servicios Básicos'!$J3) -> 5 | U3: =YEAR('Servicios Básicos'!$J3) -> 2025
A4: SERVICIOS BÁSICOS | B4: Gastos de servicios básicos | C4: 161001 | D4: 987654321 | E4: 965687408 | F4: Morat Gas | G4: Factura | H4: 11280187 | I4: 45673 | J4: 45701 | K4: Transferencia electrónica | L4: 2998926 | M4: 2998926 | N4: Gas Procesos Planta | T4: =MONTH('Servicios Básicos'!$J4) -> 2 | U4: =YEAR('Servicios Básicos'!$J4) -> 2025
A5: SERVICIOS BÁSICOS | B5: Gastos de servicios básicos | C5: 161001 | D5: 987654321 | E5: 769655158 | F5: Cabas Luz | G5: Factura | H5: 4250 | I5: 45716 | J5: 45743 | K5: Transferencia electrónica | L5: 2018386 | M5: 2018386 | N5: Energia Electrica | T5: =MONTH('Servicios Básicos'!$J5) -> 3 | U5: =YEAR('Servicios Básicos'!$J5) -> 2025
A6: SERVICIOS BÁSICOS | B6: Gastos de servicios básicos | C6: 161001 | D6: 987654321 | E6: 965687408 | F6: Morat Gas | G6: Factura | H6: 11724541 | I6: 45897 | J6: 45953 | K6: Transferencia electrónica | L6: 854685 | M6: 854685 | N6: Gas | T6: =MONTH('Servicios Básicos'!$J6) -> 10 | U6: =YEAR('Servicios Básicos'!$J6) -> 2025
A7: SERVICIOS BÁSICOS | B7: Gastos de servicios básicos | C7: 161001 | D7: 987654321 | E7: 769655158 | F7: Cabas Luz | G7: Factura | H7: 4824 | I7: 45838 | J7: 45862 | K7: Transferencia electrónica | L7: 762188 | M7: 762188 | N7: Energia electrica junio | T7: =MONTH('Servicios Básicos'!$J7) -> 7 | U7: =YEAR('Servicios Básicos'!$J7) -> 2025
A8: SERVICIOS BÁSICOS | B8: Gastos de servicios básicos | C8: 161001 | D8: 987654321 | E8: 965687408 | F8: Morat Gas | G8: Factura | H8: 11658668 | I8: 45849 | J8: 45876 | K8: Transferencia electrónica | L8: 1083870 | M8: 1083870 | N8: Gas domestico | T8: =MONTH('Servicios Básicos'!$J8) -> 8 | U8: =YEAR('Servicios Básicos'!$J8) -> 2025
A9: SERVICIOS BÁSICOS | B9: Gastos de servicios básicos | C9: 161001 | D9: 987654321 | E9: 769655158 | F9: Cabas Luz | G9: Factura | H9: 4959 | I9: 45869 | J9: 45904 | K9: Transferencia electrónica | L9: 1146884 | M9: =L9 -> 1146884 | N9: Consumo energia planta fotovoltaica Los Romos Julio | T9: =MONTH('Servicios Básicos'!$J9) -> 9 | U9: =YEAR('Servicios Básicos'!$J9) -> 2025
A10: Total | L10: =SUM(L2:L9) -> 13077219 | M10: =SUM(Valor_Rendido_Basicos) -> 13077219 | T10: =MONTH('Servicios Básicos'!$J10) -> 1 | U10: =YEAR('Servicios Básicos'!$J10) -> 1900

Sheet Inversión
A1: Cuenta | B1: Ítem | C1: Nombre del Activo | D1: Código | E1: RUT Contribuyente | F1: RUT Proveedor | G1: Nombre Proveedor o Razón Social | H1: N° de Documento | I1: Fecha Emision Documento | J1: Fecha de Activación | K1: Monto Total Documento (V. Neto) | L1: Monto total activado | M1: Cod. Vida útil en tabla del SII | N1: Años vida útil del activo | O1: Meses a Depreciar Periodo de Rendición | P1: Monto a Depreciar Periodo de Rendición | Q1: Código del proyecto en que fue activado | R1: Cuotas utilizadas antes de la actual rendición | S1: Glosa / Justificación | U1: Documento Tributario | V1: Comprobante de pago | W1: Cuadro de activación | X1: Observaciones
A2: GASTOS DE INVERSIÓN | D2: =IFERROR(VLOOKUP(C2,#REF!,5,FALSE),"") | P2: =+ROUND((L2*O2)/(N2*12),) -> #DIV/0! | U2: CON OBSERVACIONES | V2: OK
A3: GASTOS DE INVERSIÓN | D3: =IFERROR(VLOOKUP(C3,#REF!,5,FALSE),"") | P3: =+ROUND((L3*O3)/(N3*12),) -> #DIV/0!
A4: GASTOS DE INVERSIÓN | D4: =IFERROR(VLOOKUP(C4,#REF!,5,FALSE),"") | P4: =+ROUND((L4*O4)/(N4*12),) -> #DIV/0!
A5: GASTOS DE INVERSIÓN | D5: =IFERROR(VLOOKUP(C5,#REF!,5,FALSE),"") | P5: =+ROUND((L5*O5)/(N5*12),) -> #DIV/0!
A6: Total | P6: =SUBTOTAL(109,P2:P5) -> #DIV/0!
B10: TIPS DE INGRESO DE INFORMACIÓN (ELIMINAR ANTES DE ENVIAR A CLIENTE) Gastos en bienes físicos del Activo Inmovilizado Adquisición y fabricación de equipos e instrumental: Corresponde gastos incurridos en la adquisición o fabricación de equipos e instrumental requerido para la ejecución de un proyecto. Se incluyen gastos de seguros, traslado e internación, y todos los accesorios necesarios para el funcionamiento y puesta en marcha de los activos señalados. Edificación e Infraestructura, adquisición o compra de inmuebles: Corresponde a desembolsos asociados a la inversión en edificación e infraestructura y aquellas inversiones para la adquisición o compra de inmuebles requeridos para la ejecución de un proyecto, tales como: ▪Construcción de laboratorios, edificios, plantas pilotos, talleres, bodegas, adecuación de infraestructuras, entre otros de similar naturaleza. ▪Adquisición o compra de inmuebles, tales como laboratorios, talleres, bodegas, edificios, entre otros de similar naturaleza. ▪Otros de similar naturaleza, necesarios y relacionados directamente con la ejecución del proyecto.
D12: IMPORTANTE | F12: Cuando una inversión se realiza en más de una factura, debe tener un tratamiento especial la presentación en sistema (debe ir consolidado en una sola línea). Coordinar con Sol la explicación.
D14: RUT Proveedor | F14: En el caso de que proveedor sea internacional, completar con 999999999
D16: ÍTEM / NOMBRE DEL ACTIVO | F16: Se debe actualizar la lista desplegable desde el disponible. Considerar: DATOS>VALIDACIÓN DE DATOS>PERMITIR: LISTA
C18: EQUIPAMIENTO | D18: TIPO DOCUMENTO | F18: Facturas de Adquisición: Que reflejen la compra de activos como maquinaria o equipos.
D20: DEPRECIACIÓN | F20: Documentación Contable: Que registre la incorporación del activo en el patrimonio de la empresa. Cálculo de la Depreciación: Detalles del cálculo de la depreciación del activo.
C22: INFRAESTRUCTURA | D22: TIPO DOCUMENTO | F22: Contratos de Construcción: Detallando las condiciones de la obra, materiales, plazos y costos, firmados por las partes involucradas. Facturas: Por la compra de materiales y servicios relacionados.
D24: DEPRECIACIÓN | F24: Cálculo de la Depreciación: Detalles del cálculo de la depreciación del activo.
D26: GLOSA | F26: Revisar siempre que la glosa se encuentre en una sola línea y no contenga comas. Para separar elementos utilizar un guion.
F27: EJEMPLOS: Materiales de laboratorio, vidrio -> DEBE DECIR: Materiales de laboratorio - vidrio Materiales de -> DEBE DECIR: Materiales de laboratorio Laboratorio
